<?xml version="1.0"?>
<robot name="differential_drive_robot">

  <!-- Base Link -->
  <link name="base_link">
    <visual>
      <geometry>
        <box size="0.8 0.7 0.2"/>
      </geometry>
      <material name="blue">
        <color rgba="0.0 0.0 0.8 1.0"/>
      </material>
    </visual>
    <collision>
      <geometry>
        <box size="0.8 0.7 0.2"/>
      </geometry>
    </collision>
  </link>

  <!-- Wheels -->
  <link name="left_wheel">
    <visual>
      <geometry>
        <cylinder length="0.1" radius="0.125"/>
      </geometry>
      <material name="black">
        <color rgba="0.0 0.0 0.0 1.0"/>
      </material>
    </visual>
    <collision>
      <geometry>
        <cylinder length="0.1" radius="0.125"/>
      </geometry>
    </collision>
  </link>

  <link name="right_wheel">
    <visual>
      <geometry>
        <cylinder length="0.1" radius="0.125"/>
      </geometry>
      <material name="black"/>
    </visual>
    <collision>
      <geometry>
        <cylinder length="0.1" radius="0.125"/>
      </geometry>
    </collision>
  </link>

  <!-- Wheel Joints -->
  <joint name="left_wheel_joint" type="continuous">
    <parent link="base_link"/>
    <child link="left_wheel"/>
    <origin xyz="0 0.3225 -0.055" rpy="1.5708 0 0"/>
    <axis xyz="0 1 0"/>
  </joint>

  <joint name="right_wheel_joint" type="continuous">
    <parent link="base_link"/>
    <child link="right_wheel"/>
    <origin xyz="0 -0.3225 -0.055" rpy="1.5708 0 0"/>
    <axis xyz="0 1 0"/>
  </joint>

  <!-- Castor (Slippery Sphere) -->
  <link name="castor">
    <visual>
      <geometry>
        <sphere radius="0.05"/>
      </geometry>
      <material name="grey">
        <color rgba="0.5 0.5 0.5 1.0"/>
      </material>
    </visual>
    <collision>
      <geometry>
        <sphere radius="0.05"/>
      </geometry>
    </collision>
  </link>

  <joint name="castor_joint" type="fixed">
    <parent link="base_link"/>
    <child link="castor"/>
    <origin xyz="-0.5 0 -0.13"/>
  </joint>

  <!-- Odom Frame -->
  <link name="odom"/>
  <joint name="odom_joint" type="fixed">
    <parent link="base_link"/>
    <child link="odom"/>
    <origin xyz="-0.185 0 0.32"/>
  </joint>

  <!-- Velodyne Frame -->
  <link name="velodyne"/>
  <joint name="velodyne_joint" type="fixed">
    <parent link="base_link"/>
    <child link="velodyne"/>
    <origin xyz="-0.415 0 0.445"/>
  </joint>

</robot>